<?xml version="1.0"?>
<mujoco model="triple_pendulum_mjcf">
  <compiler angle="radian" balanceinertia="true" discardvisual="false"/>
  <option gravity="0 0 -9.81"/>

  <worldbody>
    <light directional="false" pos="0 0 2" diffuse="0.8 0.8 0.8"/>
    <body name="link_1" pos="0 0 0">
      <joint name="joint_1" type="hinge" axis="0 1 0" limited="false"/>
      <inertial pos="0 0 -0.15" mass="1.20" diaginertia="0.003 0.003 0.003"/>
      <geom name="joint1_vis" type="cylinder" size="0.04 0.03"
            pos="0 0 0" euler="1.5708 0 0" rgba="0.12 0.35 0.90 1"/>
      <geom name="link1_box" type="box" size="0.03 0.03 0.15"
            pos="0 0 -0.15" rgba="0.78 0.78 0.78 1"/>
      <body name="link_2" pos="0 0 -0.30">
        <joint name="joint_2" type="hinge" axis="0 1 0" limited="false"/>
        <inertial pos="0.175 0 0" mass="1.00" diaginertia="0.0025 0.0025 0.0025"/>
        <geom name="joint2_vis" type="cylinder" size="0.04 0.03"
              pos="0 0 0" euler="1.5708 0 0" rgba="0.12 0.35 0.90 1"/>
        <geom name="link2_box" type="box" size="0.03 0.03 0.175"
              pos="0.175 0 0" euler="0 1.5708 0" rgba="0.78 0.78 0.78 1"/>
        <body name="link_3" pos="0.35 0 0" euler="0 -0.785398 0">
          <joint name="joint_3" type="hinge" axis="0 1 0" limited="false"/>
          <inertial pos="0.225 0 0" mass="0.95" diaginertia="0.002 0.002 0.002"/>
          <geom name="joint3_vis" type="cylinder" size="0.04 0.03"
                pos="0 0 0" euler="1.5708 0 0" rgba="0.12 0.35 0.90 1"/>
          <geom name="link3_box" type="box" size="0.03 0.03 0.225"
                pos="0.225 0 0" euler="0 1.5708 0" rgba="0.78 0.78 0.78 1"/>
        </body> 
      </body> 
    </body> 
  </worldbody>
</mujoco>
