<?xml version="1.0"?>
<robot name="triple_pendulum_standard">

  <mujoco>
    <compiler balanceinertia="true" discardvisual="false" meshdir="meshes" fusestatic="false"/>
  </mujoco>

  <link name="world"/>

  <link name="link_1">
    <visual>
      <geometry>
        <cylinder radius="0.04" length="0.06"/>
      </geometry>
      <origin xyz="0 0 0" rpy="1.5708 0 0"/>
      <material name="blue_joint"/>
    </visual>

    <visual>
      <geometry>
        <box size="0.03 0.03 0.30"/>
      </geometry>
      <origin xyz="0 0 -0.15" rpy="0 0 0"/>
      <material name="gray_link"/>
    </visual>

    <collision>
      <geometry>
        <box size="0.03 0.03 0.30"/>
      </geometry>
      <origin xyz="0 0 -0.15" rpy="0 0 0"/>
    </collision>

    <inertial>
      <mass value="1.2"/>
      <inertia ixx="0.003" iyy="0.003" izz="0.003" ixy="0" ixz="0" iyz="0"/>
      <origin xyz="0 0 -0.15" rpy="0 0 0"/>
    </inertial>
  </link>

  <joint name="joint_1" type="revolute">
    <parent link="world"/>
    <child link="link_1"/>
    <origin xyz="0 0 0" rpy="0 0 0"/>
    <axis xyz="0 1 0"/>
    <limit lower="-3.14" upper="3.14" effort="20" velocity="5"/>
  </joint>

  <link name="link_2">
    <visual>
      <geometry>
        <cylinder radius="0.04" length="0.06"/>
      </geometry>
      <origin xyz="0 0 0" rpy="1.5708 0 0"/>
      <material name="blue_joint"/>
    </visual>

    <visual>
      <geometry>
        <box size="0.03 0.03 0.35"/>
      </geometry>
      <origin xyz="0.175 0 0" rpy="0 1.5708 0"/>
      <material name="gray_link"/>
    </visual>

    <collision>
      <geometry>
        <box size="0.03 0.03 0.35"/>
      </geometry>
      <origin xyz="0.175 0 0" rpy="0 1.5708 0"/>
    </collision>

    <inertial>
      <mass value="1.0"/>
      <inertia ixx="0.0025" iyy="0.0025" izz="0.0025" ixy="0" ixz="0" iyz="0"/>
      <origin xyz="0.175 0 0" rpy="0 0 0"/>
    </inertial>
  </link>

  <joint name="joint_2" type="revolute">
    <parent link="link_1"/>
    <child link="link_2"/>
    <origin xyz="0 0 -0.30" rpy="0 0 0"/>
    <axis xyz="0 1 0"/>
    <limit lower="-3.14" upper="3.14" effort="20" velocity="5"/>
  </joint>

  <link name="link_3">
    <visual>
      <geometry>
        <cylinder radius="0.04" length="0.06"/>
      </geometry>
      <origin xyz="0 0 0" rpy="1.5708 0 0"/>
      <material name="blue_joint"/>
    </visual>

    <visual>
      <geometry>
        <box size="0.03 0.03 0.45"/>
      </geometry>
      <origin xyz="0.225 0 0" rpy="0 1.5708 0"/>
      <material name="gray_link"/>
    </visual>

    <collision>
      <geometry>
        <box size="0.03 0.03 0.45"/>
      </geometry>
      <origin xyz="0.225 0 0" rpy="0 1.5708 0"/>
    </collision>

    <inertial>
      <mass value="0.9"/>
      <inertia ixx="0.002" iyy="0.002" izz="0.002" ixy="0" ixz="0" iyz="0"/>
      <origin xyz="0.225 0 0" rpy="0 0 0"/>
    </inertial>
  </link>

  <joint name="joint_3" type="revolute">
    <parent link="link_2"/>
    <child link="link_3"/>
    <origin xyz="0.35 0 0" rpy="0 -0.785398 0"/>
    <axis xyz="0 1 0"/>
    <limit lower="-3.14" upper="3.14" effort="20" velocity="5"/>
  </joint>

  <material name="gray_link">
    <color rgba="0.78 0.78 0.78 1.0"/>
  </material>

  <material name="blue_joint">
    <color rgba="0.12 0.35 0.9 1.0"/>
  </material>

</robot>
